[2023-05-11T11:07:48.490+0000] {logging_mixin.py:149} INFO - Changing /opt/***/logs/dag_id=tiktok_processing/run_id=manual__2023-05-11T11:06:58.528051+00:00/task_id=data_processing_tasks.clean_content_column_task permission to 509
[2023-05-11T11:07:48.628+0000] {logging_mixin.py:149} INFO - Changing /opt/***/logs/dag_id=tiktok_processing/run_id=manual__2023-05-11T11:06:58.528051+00:00/task_id=data_processing_tasks.clean_content_column_task permission to 509
[2023-05-11T11:07:48.876+0000] {taskinstance.py:1125} INFO - Dependencies all met for dep_context=non-requeueable deps ti=<TaskInstance: tiktok_processing.data_processing_tasks.clean_content_column_task manual__2023-05-11T11:06:58.528051+00:00 [queued]>
[2023-05-11T11:07:49.260+0000] {taskinstance.py:1125} INFO - Dependencies all met for dep_context=requeueable deps ti=<TaskInstance: tiktok_processing.data_processing_tasks.clean_content_column_task manual__2023-05-11T11:06:58.528051+00:00 [queued]>
[2023-05-11T11:07:49.260+0000] {taskinstance.py:1331} INFO - Starting attempt 1 of 1
[2023-05-11T11:07:49.676+0000] {taskinstance.py:1350} INFO - Executing <Task(PythonOperator): data_processing_tasks.clean_content_column_task> on 2023-05-11 11:06:58.528051+00:00
[2023-05-11T11:07:49.726+0000] {standard_task_runner.py:57} INFO - Started process 1916 to run task
[2023-05-11T11:07:49.744+0000] {standard_task_runner.py:84} INFO - Running: ['***', 'tasks', 'run', 'tiktok_processing', 'data_processing_tasks.clean_content_column_task', 'manual__2023-05-11T11:06:58.528051+00:00', '--job-id', '15', '--raw', '--subdir', 'DAGS_FOLDER/task_7_1.py', '--cfg-path', '/tmp/tmp_t5l3ug2']
[2023-05-11T11:07:49.757+0000] {standard_task_runner.py:85} INFO - Job 15: Subtask data_processing_tasks.clean_content_column_task
[2023-05-11T11:07:49.855+0000] {logging_mixin.py:149} WARNING - /home/***/.local/lib/python3.7/site-packages/***/settings.py:188 DeprecationWarning: The sql_alchemy_conn option in [core] has been moved to the sql_alchemy_conn option in [database] - the old setting has been used, but please update your config.
[2023-05-11T11:07:50.154+0000] {logging_mixin.py:149} INFO - Changing /opt/***/logs/dag_id=tiktok_processing/run_id=manual__2023-05-11T11:06:58.528051+00:00/task_id=data_processing_tasks.clean_content_column_task permission to 509
[2023-05-11T11:07:50.180+0000] {task_command.py:410} INFO - Running <TaskInstance: tiktok_processing.data_processing_tasks.clean_content_column_task manual__2023-05-11T11:06:58.528051+00:00 [running]> on host 49e2673af856
[2023-05-11T11:07:53.999+0000] {taskinstance.py:1570} INFO - Exporting env vars: AIRFLOW_CTX_DAG_OWNER='***' AIRFLOW_CTX_DAG_ID='tiktok_processing' AIRFLOW_CTX_TASK_ID='data_processing_tasks.clean_content_column_task' AIRFLOW_CTX_EXECUTION_DATE='2023-05-11T11:06:58.528051+00:00' AIRFLOW_CTX_TRY_NUMBER='1' AIRFLOW_CTX_DAG_RUN_ID='manual__2023-05-11T11:06:58.528051+00:00'
[2023-05-11T11:07:54.012+0000] {taskinstance.py:1847} ERROR - Task failed with exception
Traceback (most recent call last):
  File "/home/airflow/.local/lib/python3.7/site-packages/airflow/operators/python.py", line 181, in execute
    return_value = self.execute_callable()
  File "/home/airflow/.local/lib/python3.7/site-packages/airflow/operators/python.py", line 198, in execute_callable
    return self.python_callable(*self.op_args, **self.op_kwargs)
  File "/opt/airflow/dags/task_7_1.py", line 40, in clean_content_column
    df = pd.read_csv("/opt/airflow/data/sorted_tiktok_without_nulls.csv")
  File "/home/airflow/.local/lib/python3.7/site-packages/pandas/util/_decorators.py", line 311, in wrapper
    return func(*args, **kwargs)
  File "/home/airflow/.local/lib/python3.7/site-packages/pandas/io/parsers/readers.py", line 586, in read_csv
    return _read(filepath_or_buffer, kwds)
  File "/home/airflow/.local/lib/python3.7/site-packages/pandas/io/parsers/readers.py", line 482, in _read
    parser = TextFileReader(filepath_or_buffer, **kwds)
  File "/home/airflow/.local/lib/python3.7/site-packages/pandas/io/parsers/readers.py", line 811, in __init__
    self._engine = self._make_engine(self.engine)
  File "/home/airflow/.local/lib/python3.7/site-packages/pandas/io/parsers/readers.py", line 1040, in _make_engine
    return mapping[engine](self.f, **self.options)  # type: ignore[call-arg]
  File "/home/airflow/.local/lib/python3.7/site-packages/pandas/io/parsers/c_parser_wrapper.py", line 51, in __init__
    self._open_handles(src, kwds)
  File "/home/airflow/.local/lib/python3.7/site-packages/pandas/io/parsers/base_parser.py", line 229, in _open_handles
    errors=kwds.get("encoding_errors", "strict"),
  File "/home/airflow/.local/lib/python3.7/site-packages/pandas/io/common.py", line 707, in get_handle
    newline="",
FileNotFoundError: [Errno 2] No such file or directory: '/opt/airflow/data/sorted_tiktok_without_nulls.csv'
[2023-05-11T11:07:54.054+0000] {taskinstance.py:1373} INFO - Marking task as FAILED. dag_id=tiktok_processing, task_id=data_processing_tasks.clean_content_column_task, execution_date=20230511T110658, start_date=20230511T110748, end_date=20230511T110754
[2023-05-11T11:07:54.176+0000] {standard_task_runner.py:109} ERROR - Failed to execute job 15 for task data_processing_tasks.clean_content_column_task ([Errno 2] No such file or directory: '/opt/airflow/data/sorted_tiktok_without_nulls.csv'; 1916)
[2023-05-11T11:07:54.207+0000] {local_task_job_runner.py:232} INFO - Task exited with return code 1
[2023-05-11T11:07:54.256+0000] {taskinstance.py:2674} INFO - 0 downstream tasks scheduled from follow-on schedule check
