[2023-05-11T13:47:48.271+0000] {logging_mixin.py:149} INFO - Changing /opt/***/logs/dag_id=tiktok_processing/run_id=manual__2023-05-11T13:45:40.512849+00:00/task_id=data_processing_tasks.sort_by_created_date_task permission to 509
[2023-05-11T13:47:48.488+0000] {logging_mixin.py:149} INFO - Changing /opt/***/logs/dag_id=tiktok_processing/run_id=manual__2023-05-11T13:45:40.512849+00:00/task_id=data_processing_tasks.sort_by_created_date_task permission to 509
[2023-05-11T13:47:51.450+0000] {taskinstance.py:1125} INFO - Dependencies all met for dep_context=non-requeueable deps ti=<TaskInstance: tiktok_processing.data_processing_tasks.sort_by_created_date_task manual__2023-05-11T13:45:40.512849+00:00 [None]>
[2023-05-11T13:47:51.483+0000] {taskinstance.py:1125} INFO - Dependencies all met for dep_context=requeueable deps ti=<TaskInstance: tiktok_processing.data_processing_tasks.sort_by_created_date_task manual__2023-05-11T13:45:40.512849+00:00 [None]>
[2023-05-11T13:47:51.485+0000] {taskinstance.py:1331} INFO - Starting attempt 1 of 1
[2023-05-11T13:47:51.542+0000] {taskinstance.py:1350} INFO - Executing <Task(PythonOperator): data_processing_tasks.sort_by_created_date_task> on 2023-05-11 13:45:40.512849+00:00
[2023-05-11T13:47:51.565+0000] {standard_task_runner.py:57} INFO - Started process 3090 to run task
[2023-05-11T13:47:53.061+0000] {standard_task_runner.py:84} INFO - Running: ['***', 'tasks', 'run', 'tiktok_processing', 'data_processing_tasks.sort_by_created_date_task', 'manual__2023-05-11T13:45:40.512849+00:00', '--job-id', '48', '--raw', '--subdir', 'DAGS_FOLDER/task_7_1.py', '--cfg-path', '/tmp/tmphuxp7uwv']
[2023-05-11T13:47:53.287+0000] {standard_task_runner.py:85} INFO - Job 48: Subtask data_processing_tasks.sort_by_created_date_task
[2023-05-11T13:47:53.712+0000] {logging_mixin.py:149} WARNING - /home/***/.local/lib/python3.7/site-packages/***/settings.py:188 DeprecationWarning: The sql_alchemy_conn option in [core] has been moved to the sql_alchemy_conn option in [database] - the old setting has been used, but please update your config.
[2023-05-11T13:47:54.055+0000] {logging_mixin.py:149} INFO - Changing /opt/***/logs/dag_id=tiktok_processing/run_id=manual__2023-05-11T13:45:40.512849+00:00/task_id=data_processing_tasks.sort_by_created_date_task permission to 509
[2023-05-11T13:47:54.223+0000] {task_command.py:410} INFO - Running <TaskInstance: tiktok_processing.data_processing_tasks.sort_by_created_date_task manual__2023-05-11T13:45:40.512849+00:00 [running]> on host d8f273d8514c
[2023-05-11T13:47:54.847+0000] {taskinstance.py:1570} INFO - Exporting env vars: AIRFLOW_CTX_DAG_OWNER='***' AIRFLOW_CTX_DAG_ID='tiktok_processing' AIRFLOW_CTX_TASK_ID='data_processing_tasks.sort_by_created_date_task' AIRFLOW_CTX_EXECUTION_DATE='2023-05-11T13:45:40.512849+00:00' AIRFLOW_CTX_TRY_NUMBER='1' AIRFLOW_CTX_DAG_RUN_ID='manual__2023-05-11T13:45:40.512849+00:00'
[2023-05-11T13:54:10.553+0000] {local_task_job_runner.py:299} WARNING - State of this instance has been externally set to None. Terminating instance.
[2023-05-11T13:54:11.902+0000] {process_utils.py:135} INFO - Sending Signals.SIGTERM to group 3090. PIDs of all processes in the group: [3090]
[2023-05-11T13:54:11.941+0000] {process_utils.py:86} INFO - Sending the signal Signals.SIGTERM to group 3090
[2023-05-11T13:54:12.095+0000] {taskinstance.py:1540} ERROR - Received SIGTERM. Terminating subprocesses.
[2023-05-11T13:54:13.131+0000] {taskinstance.py:1847} ERROR - Task failed with exception
Traceback (most recent call last):
  File "/home/airflow/.local/lib/python3.7/site-packages/airflow/operators/python.py", line 181, in execute
    return_value = self.execute_callable()
  File "/home/airflow/.local/lib/python3.7/site-packages/airflow/operators/python.py", line 198, in execute_callable
    return self.python_callable(*self.op_args, **self.op_kwargs)
  File "/opt/airflow/dags/task_7_1.py", line 33, in sort_by_created_date
    df = df.sort_values('created_date')
  File "/home/airflow/.local/lib/python3.7/site-packages/pandas/util/_decorators.py", line 311, in wrapper
    return func(*args, **kwargs)
  File "/home/airflow/.local/lib/python3.7/site-packages/pandas/core/frame.py", line 6277, in sort_values
    indexer, axis=self._get_block_manager_axis(axis), verify=False
  File "/home/airflow/.local/lib/python3.7/site-packages/pandas/core/internals/managers.py", line 870, in take
    consolidate=False,
  File "/home/airflow/.local/lib/python3.7/site-packages/pandas/core/internals/managers.py", line 688, in reindex_indexer
    for blk in self.blocks
  File "/home/airflow/.local/lib/python3.7/site-packages/pandas/core/internals/managers.py", line 688, in <listcomp>
    for blk in self.blocks
  File "/home/airflow/.local/lib/python3.7/site-packages/pandas/core/internals/blocks.py", line 1145, in take_nd
    values, indexer, axis=axis, allow_fill=allow_fill, fill_value=fill_value
  File "/home/airflow/.local/lib/python3.7/site-packages/pandas/core/array_algos/take.py", line 108, in take_nd
    return _take_nd_ndarray(arr, indexer, axis, fill_value, allow_fill)
  File "/home/airflow/.local/lib/python3.7/site-packages/pandas/core/array_algos/take.py", line 149, in _take_nd_ndarray
    out = np.empty(out_shape, dtype=dtype)
  File "/home/airflow/.local/lib/python3.7/site-packages/airflow/models/taskinstance.py", line 1542, in signal_handler
    raise AirflowException("Task received SIGTERM signal")
airflow.exceptions.AirflowException: Task received SIGTERM signal
[2023-05-11T13:54:13.774+0000] {taskinstance.py:1373} INFO - Marking task as FAILED. dag_id=tiktok_processing, task_id=data_processing_tasks.sort_by_created_date_task, execution_date=20230511T134540, start_date=20230511T134751, end_date=20230511T135413
[2023-05-11T13:54:14.462+0000] {standard_task_runner.py:109} ERROR - Failed to execute job 48 for task data_processing_tasks.sort_by_created_date_task (Task received SIGTERM signal; 3090)
[2023-05-11T13:54:14.808+0000] {process_utils.py:79} INFO - Process psutil.Process(pid=3090, status='terminated', exitcode=1, started='13:47:50') (3090) terminated with exit code 1
